<?xml version="1.0"?>
<robot name="sentry" xmlns:xacro="http://ros.org/wiki/xacro">
    <material name="red">
        <color rgba="1.0 0 0 1.0"/>
    </material>
    <material name="green">
        <color rgba="0 1.0 0 1.0"/>
    </material>
    <material name="yellow">
        <color rgba="1 1.0 1 1.0"/>
    </material>
    <xacro:arg name="camera_name"   default="oak" />
    <xacro:arg name="camera_model"  default="OAK-D" />
    <xacro:arg name="base_frame"    default="oak-d_frame" />
    <xacro:arg name="parent_frame"  default="base_link" />
    <xacro:arg name="cam_pos_x"     default="0.0" />
    <xacro:arg name="cam_pos_y"     default="0.0" />
    <xacro:arg name="cam_pos_z"     default="0.0" />
    <xacro:arg name="cam_roll"      default="0.0" />
    <xacro:arg name="cam_pitch"     default="0.0" />
    <xacro:arg name="cam_yaw"       default="0.0" />

    <xacro:include filename="$(find depthai_bridge)/urdf/include/depthai_macro_without_base.urdf.xacro"/>
    <!-- Base Link of robot -->
    <link name="$(arg parent_frame)"/>
    <!-- Yaw axis of robot -->
    <link name="gimbal_yaw_frame"/>
    <joint name="gimbal_yaw_joint" type="revolute">
        <axis xyz="0 0 1"/>
        <origin xyz="0 0 0.25" rpy="0 0 0" />
        <parent link="$(arg parent_frame)"/>
        <child link="gimbal_yaw_frame"/>
        <limit effort="30" velocity="10.0" lower="-3.14" upper="3.14" />
    </joint>
    <!-- Pitch axis of robot -->
    <link name="gimbal_pitch_frame"/>
    <joint name="gimbal_pitch_joint" type="revolute">
        <axis xyz="0 1 0"/>
        <origin xyz="0 0 0.25" rpy="0 0 0" />
        <parent link="gimbal_yaw_frame"/>
        <child link="gimbal_pitch_frame"/>
        <limit effort="30" velocity="10.0" lower="-3.14" upper="3.14" />
    </joint>
    <joint name="$(arg camera_name)_center_joint" type="fixed">
        <parent link="gimbal_yaw_frame"/>
        <child link="$(arg base_frame)"/>
        <origin xyz="$(arg cam_pos_x) $(arg cam_pos_y) $(arg cam_pos_z)" rpy="$(arg cam_roll) $(arg cam_pitch) $(arg cam_yaw)" />
    </joint>
    <xacro:depthai_camera camera_name = "$(arg camera_name)" parent = "$(arg parent_frame)" camera_model = "$(arg camera_model)" base_frame = "$(arg base_frame)" cam_pos_x = "$(arg cam_pos_x)" cam_pos_y = "$(arg cam_pos_y)" cam_pos_z = "$(arg cam_pos_z)" cam_roll = "$(arg cam_roll)" cam_pitch = "$(arg cam_pitch)" cam_yaw = "$(arg cam_yaw)"/>

</robot>
